Workbook

Sheet Data
A1: Generation | B1: day | C1: time_of_day | D1: Date | E1: start_time | F1: end_time | G1: Time_Elapsed | H1: Maze_Order | I1: Treatment | J1: Lineage | K1: Maze | L1: Sex | M1: 1 | N1: 2 | O1: 3 | P1: 4 | Q1: 5 | R1: 6 | S1: 7 | T1: 8 | U1: 9 | V1: 10 | W1: 11 | X1: 12 | Y1: 13 | Z1: 14 | AA1: 15 | AB1: 16 | AC1: Lightscore | AD1: total_Flies | AE1: Vials_Larvae_UsedInMaze | AF1: Vials_Total_UsedInMaze | AG1: Flies_per_Vial | AH1: flies_in | AI1: prop_out | AJ1: vials uneclosed by sexing day | AK1: start_time_num | AL1: end_time_num | AM1: time_elapsed_num | AN1: blind
A2: 1 | B2: 1 | C2: morn | D2: 24-01-2025 | E2: 0.42430556 | F2: 0.52083333 | G2: 0.096527778 | H2: ABCD | I2: S | J2: 1 | K2: A | L2: F | M2: 1 | N2: 0 | O2: 0 | P2: 0 | Q2: 2 | R2: 2 | S2: 2 | T2: 10 | U2: 4 | V2: 6 | W2: 5 | X2: 2 | Y2: 6 | Z2: 3 | AA2: 7 | AB2: 4 | AC2: =SUMPRODUCT(OG_Data!D$1:S$1, M2:AB2) /SUM(M2:AB2) -> 10.759259 | AD2: =SUM(M2:AB2) -> 54 | AH2: =Table3[[#This Row],[Flies_per_Vial]]*Table3[[#This Row],[Vials_Total_UsedInMaze]] -> 0 | AK2: =24*E2 -> 10.183333 | AL2: =24*F2 -> 12.5 | AM2: =Table3[[#This Row],[end_time_num]]-Table3[[#This Row],[start_time_num]] -> 2.3166667
A3: 1 | B3: 1 | C3: morn | D3: 24-01-2025 | E3: 0.42430556 | F3: 0.52083333 | G3: 0.096527778 | H3: ABCD | I3: S | J3: 1 | K3: B | L3: M | M3: 1 | N3: 2 | O3: 1 | P3: 1 | Q3: 2 | R3: 1 | S3: 6 | T3: 12 | U3: 10 | V3: 5 | W3: 7 | X3: 8 | Y3: 3 | Z3: 1 | AA3: 2 | AB3: 1 | AC3: =SUMPRODUCT(OG_Data!D$1:S$1, M3:AB3) /SUM(M3:AB3) -> 9.1746032 | AD3: =SUM(M3:AB3) -> 63 | AH3: =Table3[[#This Row],[Flies_per_Vial]]*Table3[[#This Row],[Vials_Total_UsedInMaze]] -> 0 | AK3: =24*E3 -> 10.183333 | AL3: =24*F3 -> 12.5 | AM3: =Table3[[#This Row],[end_time_num]]-Table3[[#This Row],[start_time_num]] -> 2.3166667
A4: 1 | B4: 1 | C4: morn | D4: 24-01-2025 | E4: 0.42430556 | F4: 0.52083333 | G4: 0.096527778 | H4: ABCD | I4: S | J4: 1 | K4: C | L4: M | M4: 0 | N4: 2 | O4: 0 | P4: 1 | Q4: 1 | R4: 0 | S4: 1 | T4: 4 | U4: 0 | V4: 0 | W4: 2 | X4: 0 | Y4: 0 | Z4: 0 | AA4: 0 | AB4: 0 | AC4: =SUMPRODUCT(OG_Data!D$1:S$1, M4:AB4) /SUM(M4:AB4) -> 6.7272727 | AD4: =SUM(M4:AB4) -> 11 | AH4: =Table3[[#This Row],[Flies_per_Vial]]*Table3[[#This Row],[Vials_Total_UsedInMaze]] -> 0 | AK4: =24*E4 -> 10.183333 | AL4: =24*F4 -> 12.5 | AM4: =Table3[[#This Row],[end_time_num]]-Table3[[#This Row],[start_time_num]] -> 2.3166667
A5: 1 | B5: 1 | C5: morn | D5: 24-01-2025 | E5: 0.42430556 | F5: 0.52083333 | G5: 0.096527778 | H5: ABCD | I5: S | J5: 1 | K5: D | L5: F | M5: 2 | N5: 1 | O5: 2 | P5: 0 | Q5: 0 | R5: 0 | S5: 0 | T5: 0 | U5: 2 | V5: 1 | W5: 0 | X5: 2 | Y5: 1 | Z5: 1 | AA5: 1 | AB5: 0 | AC5: =SUMPRODUCT(OG_Data!D$1:S$1, M5:AB5) /SUM(M5:AB5) -> 8 | AD5: =SUM(M5:AB5) -> 13 | AH5: =Table3[[#This Row],[Flies_per_Vial]]*Table3[[#This Row],[Vials_Total_UsedInMaze]] -> 0 | AK5: =24*E5 -> 10.183333 | AL5: =24*F5 -> 12.5 | AM5: =Table3[[#This Row],[end_time_num]]-Table3[[#This Row],[start_time_num]] -> 2.3166667
A6: 1 | B6: 1 | C6: aft | D6: 24-01-2025 | E6: 0.64236111 | F6: 0.7625 | G6: 0.12013889 | H6: ABCD | I6: S | J6: 2 | K6: A | L6: F | M6: 1 | N6: 1 | O6: 0 | P6: 0 | Q6: 0 | R6: 6 | S6: 2 | T6: 11 | U6: 7 | V6: 15 | W6: 3 | X6: 6 | Y6: 7 | Z6: 9 | AA6: 5 | AB6: 8 | AC6: =SUMPRODUCT(OG_Data!D$1:S$1, M6:AB6) /SUM(M6:AB6) -> 10.851852 | AD6: =SUM(M6:AB6) -> 81 | AH6: =Table3[[#This Row],[Flies_per_Vial]]*Table3[[#This Row],[Vials_Total_UsedInMaze]] -> 0 | AK6: =24*E6 -> 15.416667 | AL6: =24*F6 -> 18.3 | AM6: =Table3[[#This Row],[end_time_num]]-Table3[[#This Row],[start_time_num]] -> 2.8833333
A7: 1 | B7: 1 | C7: aft | D7: 24-01-2025 | E7: 0.64236111 | F7: 0.7625 | G7: 0.12013889 | H7: ABCD | I7: S | J7: 2 | K7: B | L7: M | M7: 1 | N7: 3 | O7: 2 | P7: 1 | Q7: 2 | R7: 2 | S7: 7 | T7: 7 | U7: 8 | V7: 9 | W7: 4 | X7: 13 | Y7: 10 | Z7: 8 | AA7: 1 | AB7: 5 | AC7: =SUMPRODUCT(OG_Data!D$1:S$1, M7:AB7) /SUM(M7:AB7) -> 10.156627 | AD7: =SUM(M7:AB7) -> 83 | AH7: =Table3[[#This Row],[Flies_per_Vial]]*Table3[[#This Row],[Vials_Total_UsedInMaze]] -> 0 | AK7: =24*E7 -> 15.416667 | AL7: =24*F7 -> 18.3 | AM7: =Table3[[#This Row],[end_time_num]]-Table3[[#This Row],[start_time_num]] -> 2.8833333
A8: 1 | B8: 1 | C8: aft | D8: 24-01-2025 | E8: 0.64236111 | F8: 0.7625 | G8: 0.12013889 | H8: ABCD | I8: S | J8: 2 | K8: C | L8: M | M8: 0 | N8: 0 | O8: 0 | P8: 0 | Q8: 0 | R8: 0 | S8: 1 | T8: 2 | U8: 1 | V8: 0 | W8: 6 | X8: 3 | Y8: 0 | Z8: 1 | AA8: 2 | AB8: 1 | AC8: =SUMPRODUCT(OG_Data!D$1:S$1, M8:AB8) /SUM(M8:AB8) -> 11.411765 | AD8: =SUM(M8:AB8) -> 17 | AH8: =Table3[[#This Row],[Flies_per_Vial]]*Table3[[#This Row],[Vials_Total_UsedInMaze]] -> 0 | AK8: =24*E8 -> 15.416667 | AL8: =24*F8 -> 18.3 | AM8: =Table3[[#This Row],[end_time_num]]-Table3[[#This Row],[start_time_num]] -> 2.8833333
A9: 1 | B9: 1 | C9: aft | D9: 24-01-2025 | E9: 0.64236111 | F9: 0.7625 | G9: 0.12013889 | H9: ABCD | I9: S | J9: 2 | K9: D | L9: F | M9: 0 | N9: 2 | O9: 0 | P9: 2 | Q9: 0 | R9: 0 | S9: 1 | T9: 0 | U9: 0 | V9: 0 | W9: 0 | X9: 0 | Y9: 1 | Z9: 0 | AA9: 0 | AB9: 0 | AC9: =SUMPRODUCT(OG_Data!D$1:S$1, M9:AB9) /SUM(M9:AB9) -> 5.3333333 | AD9: =SUM(M9:AB9) -> 6 | AH9: =Table3[[#This Row],[Flies_per_Vial]]*Table3[[#This Row],[Vials_Total_UsedInMaze]] -> 0 | AK9: =24*E9 -> 15.416667 | AL9: =24*F9 -> 18.3 | AM9: =Table3[[#This Row],[end_time_num]]-Table3[[#This Row],[start_time_num]] -> 2.8833333
A10: 1 | B10: 2 | C10: morn | D10: 25-01-2025 | E10: 0.38263889 | F10: 0.4375 | G10: 0.054861111 | H10: ABCD | I10: S | J10: 3 | K10: A | L10: M | M10: 0 | N10: 1 | O10: 0 | P10: 0 | Q10: 1 | R10: 1 | S10: 1 | T10: 4 | U10: 6 | V10: 6 | W10: 4 | X10: 0 | Y10: 0 | Z10: 1 | AA10: 1 | AB10: 0 | AC10: =SUMPRODUCT(OG_Data!D$1:S$1, M10:AB10) /SUM(M10:AB10) -> 9.1923077 | AD10: =SUM(M10:AB10) -> 26 | AH10: =Table3[[#This Row],[Flies_per_Vial]]*Table3[[#This Row],[Vials_Total_UsedInMaze]] -> 0 | AK10: =24*E10 -> 9.1833333 | AL10: =24*F10 -> 10.5 | AM10: =Table3[[#This Row],[end_time_num]]-Table3[[#This Row],[start_time_num]] -> 1.3166667
A11: 1 | B11: 2 | C11: morn | D11: 25-01-2025 | E11: 0.38263889 | F11: 0.4375 | G11: 0.054861111 | H11: ABCD | I11: S | J11: 3 | K11: B | L11: F | M11: 1 | N11: 2 | O11: 0 | P11: 0 | Q11: 3 | R11: 0 | S11: 6 | T11: 8 | U11: 3 | V11: 7 | W11: 5 | X11: 5 | Y11: 9 | Z11: 7 | AA11: 5 | AB11: 2 | AC11: =SUMPRODUCT(OG_Data!D$1:S$1, M11:AB11) /SUM(M11:AB11) -> 10.47619 | AD11: =SUM(M11:AB11) -> 63 | AH11: =Table3[[#This Row],[Flies_per_Vial]]*Table3[[#This Row],[Vials_Total_UsedInMaze]] -> 0 | AK11: =24*E11 -> 9.1833333 | AL11: =24*F11 -> 10.5 | AM11: =Table3[[#This Row],[end_time_num]]-Table3[[#This Row],[start_time_num]] -> 1.3166667
A12: 1 | B12: 2 | C12: morn | D12: 25-01-2025 | E12: 0.46875 | F12: 0.53125 | G12: 0.0625 | H12: ABCD | I12: S | J12: 3 | K12: A | L12: M | M12: 0 | N12: 4 | O12: 2 | P12: 0 | Q12: 3 | R12: 4 | S12: 4 | T12: 11 | U12: 7 | V12: 7 | W12: 15 | X12: 10 | Y12: 5 | Z12: 10 | AA12: 2 | AB12: 2 | AC12: =SUMPRODUCT(OG_Data!D$1:S$1, M12:AB12) /SUM(M12:AB12) -> 9.9302326 | AD12: =SUM(M12:AB12) -> 86 | AH12: =Table3[[#This Row],[Flies_per_Vial]]*Table3[[#This Row],[Vials_Total_UsedInMaze]] -> 0 | AK12: =24*E12 -> 11.25 | AL12: =24*F12 -> 12.75 | AM12: =Table3[[#This Row],[end_time_num]]-Table3[[#This Row],[start_time_num]] -> 1.5
A13: 1 | B13: 2 | C13: morn | D13: 25-01-2025 | E13: 0.46875 | F13: 0.53125 | G13: 0.0625 | H13: ABCD | I13: S | J13: 3 | K13: B | L13: F | M13: 4 | N13: 8 | O13: 8 | P13: 4 | Q13: 4 | R13: 5 | S13: 6 | T13: 11 | U13: 9 | V13: 6 | W13: 10 | X13: 9 | Y13: 3 | Z13: 1 | AA13: 3 | AB13: 2 | AC13: =SUMPRODUCT(OG_Data!D$1:S$1, M13:AB13) /SUM(M13:AB13) -> 7.8387097 | AD13: =SUM(M13:AB13) -> 93 | AH13: =Table3[[#This Row],[Flies_per_Vial]]*Table3[[#This Row],[Vials_Total_UsedInMaze]] -> 0 | AK13: =24*E13 -> 11.25 | AL13: =24*F13 -> 12.75 | AM13: =Table3[[#This Row],[end_time_num]]-Table3[[#This Row],[start_time_num]] -> 1.5
... A27: 1 | B27: 3 | C27: aft | D27: 26-01-2025 | E27: 0.67916667 | F27: 0.79166667 | G27: 0.1125 | H27: ABCD | I27: C | J27: 4 | K27: B | L27: F | M27: 14 | N27: 13 | O27: 4 | P27: 1 | Q27: 2 | R27: 2 | S27: 4 | T27: 4 | U27: 3 | V27: 4 | W27: 1 | X27: 3 | Y27: 6 | Z27: 7 | AA27: 6 | AB27: 8 | AC27: =SUMPRODUCT(OG_Data!D$1:S$1, M27:AB27) /SUM(M27:AB27) -> 7.8780488 | AD27: =SUM(M27:AB27) -> 82 | AH27: =Table3[[#This Row],[Flies_per_Vial]]*Table3[[#This Row],[Vials_Total_UsedInMaze]] -> 0 | AK27: =24*E27 -> 16.3 | AL27: =24*F27 -> 19 | AM27: =Table3[[#This Row],[end_time_num]]-Table3[[#This Row],[start_time_num]] -> 2.7
A28: 2 | B28: 1 | C28: morn | D28: 05-02-2025 | E28: 0.46319444 | H28: ABCD | I28: S | J28: 1 | K28: A | L28: F | M28: 0 | N28: 0 | O28: 1 | P28: 2 | Q28: 2 | R28: 2 | S28: 2 | T28: 4 | U28: 9 | V28: 10 | W28: 10 | X28: 7 | Y28: 4 | Z28: 2 | AA28: 14 | AB28: 3 | AC28: =SUMPRODUCT(OG_Data!D$1:S$1, M28:AB28) /SUM(M28:AB28) -> 11 | AD28: =SUM(M28:AB28) -> 72 | AH28: =Table3[[#This Row],[Flies_per_Vial]]*Table3[[#This Row],[Vials_Total_UsedInMaze]] -> 0 | AK28: =24*E28 -> 11.116667
A29: 2 | B29: 1 | C29: morn | D29: 05-02-2025 | E29: 0.46319444 | H29: ABCD | I29: S | J29: 1 | K29: B | L29: M | M29: 0 | N29: 3 | O29: 2 | P29: 2 | Q29: 3 | R29: 3 | S29: 12 | T29: 11 | U29: 10 | V29: 9 | W29: 9 | X29: 4 | Y29: 7 | Z29: 5 | AA29: 6 | AB29: 2 | AC29: =SUMPRODUCT(OG_Data!D$1:S$1, M29:AB29) /SUM(M29:AB29) -> 9.4886364 | AD29: =SUM(M29:AB29) -> 88 | AH29: =Table3[[#This Row],[Flies_per_Vial]]*Table3[[#This Row],[Vials_Total_UsedInMaze]] -> 0 | AK29: =24*E29 -> 11.116667
A30: 2 | B30: 1 | C30: morn | D30: 05-02-2025 | E30: 0.46319444 | H30: ABCD | I30: S | J30: 1 | K30: C | L30: M | M30: 1 | N30: 6 | O30: 5 | P30: 2 | Q30: 3 | R30: 4 | S30: 3 | T30: 3 | U30: 3 | V30: 3 | W30: 2 | X30: 1 | Y30: 1 | Z30: 0 | AA30: 1 | AB30: 5 | AC30: =SUMPRODUCT(OG_Data!D$1:S$1, M30:AB30) /SUM(M30:AB30) -> 7.4186047 | AD30: =SUM(M30:AB30) -> 43 | AH30: =Table3[[#This Row],[Flies_per_Vial]]*Table3[[#This Row],[Vials_Total_UsedInMaze]] -> 0 | AK30: =24*E30 -> 11.116667
A31: 2 | B31: 1 | C31: morn | D31: 05-02-2025 | E31: 0.46319444 | H31: ABCD | I31: S | J31: 1 | K31: D | L31: F | M31: 0 | N31: 3 | O31: 6 | P31: 5 | Q31: 10 | R31: 7 | S31: 11 | T31: 10 | U31: 6 | V31: 3 | W31: 9 | X31: 9 | Y31: 2 | Z31: 3 | AA31: 0 | AB31: 0 | AC31: =SUMPRODUCT(OG_Data!D$1:S$1, M31:AB31) /SUM(M31:AB31) -> 7.7619048 | AD31: =SUM(M31:AB31) -> 84 | AH31: =Table3[[#This Row],[Flies_per_Vial]]*Table3[[#This Row],[Vials_Total_UsedInMaze]] -> 0 | AK31: =24*E31 -> 11.116667
A32: 2 | B32: 1 | C32: aft | D32: 05-02-2025 | E32: 0.59375 | H32: ABCD | I32: S | J32: 2 | K32: A | L32: F | M32: 0 | N32: 0 | O32: 0 | P32: 0 | Q32: 0 | R32: 1 | S32: 5 | T32: 3 | U32: 13 | V32: 19 | W32: 17 | X32: 12 | Y32: 23 | Z32: 5 | AA32: 7 | AB32: 3 | AC32: =SUMPRODUCT(OG_Data!D$1:S$1, M32:AB32) /SUM(M32:AB32) -> 11.342593 | AD32: =SUM(M32:AB32) -> 108 | AH32: =Table3[[#This Row],[Flies_per_Vial]]*Table3[[#This Row],[Vials_Total_UsedInMaze]] -> 0 | AK32: =24*E32 -> 14.25
A33: 2 | B33: 1 | C33: aft | D33: 05-02-2025 | E33: 0.59375 | H33: ABCD | I33: S | J33: 2 | K33: B | L33: M | M33: 11 | N33: 0 | O33: 8 | P33: 3 | Q33: 6 | R33: 4 | S33: 8 | T33: 8 | U33: 6 | V33: 7 | W33: 4 | X33: 4 | Y33: 2 | Z33: 4 | AA33: 0 | AB33: 0 | AC33: =SUMPRODUCT(OG_Data!D$1:S$1, M33:AB33) /SUM(M33:AB33) -> 6.92 | AD33: =SUM(M33:AB33) -> 75 | AH33: =Table3[[#This Row],[Flies_per_Vial]]*Table3[[#This Row],[Vials_Total_UsedInMaze]] -> 0 | AK33: =24*E33 -> 14.25
A34: 2 | B34: 1 | C34: aft | D34: 05-02-2025 | E34: 0.59375 | H34: ABCD | I34: S | J34: 2 | K34: C | L34: M | M34: 11 | N34: 14 | O34: 25 | P34: 1 | Q34: 9 | R34: 16 | S34: 5 | T34: 4 | U34: 2 | V34: 0 | W34: 1 | X34: 1 | Y34: 1 | Z34: 1 | AA34: 0 | AB34: 0 | AC34: =SUMPRODUCT(OG_Data!D$1:S$1, M34:AB34) /SUM(M34:AB34) -> 4.3296703 | AD34: =SUM(M34:AB34) -> 91 | AH34: =Table3[[#This Row],[Flies_per_Vial]]*Table3[[#This Row],[Vials_Total_UsedInMaze]] -> 0 | AK34: =24*E34 -> 14.25
A35: 2 | B35: 1 | C35: aft | D35: 05-02-2025 | E35: 0.59375 | H35: ABCD | I35: S | J35: 2 | K35: D | L35: F | M35: 0 | N35: 3 | O35: 5 | P35: 5 | Q35: 10 | R35: 7 | S35: 7 | T35: 12 | U35: 9 | V35: 13 | W35: 14 | X35: 5 | Y35: 2 | Z35: 0 | AA35: 0 | AB35: 0 | AC35: =SUMPRODUCT(OG_Data!D$1:S$1, M35:AB35) /SUM(M35:AB35) -> 7.923913 | AD35: =SUM(M35:AB35) -> 92 | AH35: =Table3[[#This Row],[Flies_per_Vial]]*Table3[[#This Row],[Vials_Total_UsedInMaze]] -> 0 | AK35: =24*E35 -> 14.25
A36: 2 | B36: 2 | C36: morn | D36: 06-02-2025 | E36: 0.43055556 | H36: ABCD | I36: S | J36: 3 | K36: A | L36: F | M36: 0 | N36: 1 | O36: 0 | P36: 6 | Q36: 1 | R36: 1 | S36: 3 | T36: 5 | U36: 10 | V36: 13 | W36: 11 | X36: 6 | Y36: 2 | Z36: 6 | AA36: 21 | AB36: 15 | AC36: =SUMPRODUCT(OG_Data!D$1:S$1, M36:AB36) /SUM(M36:AB36) -> 11.643564 | AD36: =SUM(M36:AB36) -> 101 | AH36: =Table3[[#This Row],[Flies_per_Vial]]*Table3[[#This Row],[Vials_Total_UsedInMaze]] -> 0 | AK36: =24*E36 -> 10.333333
A37: 2 | B37: 2 | C37: morn | D37: 06-02-2025 | E37: 0.43055556 | H37: ABCD | I37: S | J37: 3 | K37: B | L37: M | M37: 4 | N37: 4 | O37: 2 | P37: 0 | Q37: 0 | R37: 2 | S37: 8 | T37: 10 | U37: 6 | V37: 8 | W37: 6 | X37: 10 | Y37: 5 | Z37: 8 | AA37: 4 | AB37: 4 | AC37: =SUMPRODUCT(OG_Data!D$1:S$1, M37:AB37) /SUM(M37:AB37) -> 9.7160494 | AD37: =SUM(M37:AB37) -> 81 | AH37: =Table3[[#This Row],[Flies_per_Vial]]*Table3[[#This Row],[Vials_Total_UsedInMaze]] -> 0 | AK37: =24*E37 -> 10.333333
A38: 2 | B38: 2 | C38: morn | D38: 06-02-2025 | E38: 0.43055556 | H38: ABCD | I38: S | J38: 3 | K38: C | L38: M | M38: 6 | N38: 4 | O38: 0 | P38: 10 | Q38: 5 | R38: 6 | S38: 6 | T38: 11 | U38: 5 | V38: 4 | W38: 1 | X38: 7 | Y38: 2 | Z38: 3 | AA38: 0 | AB38: 0 | AC38: =SUMPRODUCT(OG_Data!D$1:S$1, M38:AB38) /SUM(M38:AB38) -> 7.0428571 | AD38: =SUM(M38:AB38) -> 70 | AH38: =Table3[[#This Row],[Flies_per_Vial]]*Table3[[#This Row],[Vials_Total_UsedInMaze]] -> 0 | AK38: =24*E38 -> 10.333333
A39: 2 | B39: 2 | C39: morn | D39: 06-02-2025 | E39: 0.43055556 | H39: ABCD | I39: S | J39: 3 | K39: D | L39: F | M39: 2 | N39: 4 | O39: 4 | P39: 2 | Q39: 11 | R39: 1 | S39: 0 | T39: 11 | U39: 6 | V39: 5 | W39: 4 | X39: 8 | Y39: 0 | Z39: 0 | AA39: 0 | AB39: 0 | AC39: =SUMPRODUCT(OG_Data!D$1:S$1, M39:AB39) /SUM(M39:AB39) -> 7.2931034 | AD39: =SUM(M39:AB39) -> 58 | AH39: =Table3[[#This Row],[Flies_per_Vial]]*Table3[[#This Row],[Vials_Total_UsedInMaze]] -> 0 | AK39: =24*E39 -> 10.333333
... A43: 2 | B43: 2 | C43: aft | D43: 06-02-2025 | E43: 0.54444444 | H43: ABCD | I43: S | J43: 4 | K43: D | L43: F | M43: 1 | N43: 10 | O43: 7 | P43: 6 | Q43: 2 | R43: 2 | S43: 0 | T43: 12 | U43: 8 | V43: 3 | W43: 1 | X43: 1 | Y43: 0 | Z43: 1 | AA43: 0 | AB43: 0 | AC43: =SUMPRODUCT(OG_Data!D$1:S$1, M43:AB43) /SUM(M43:AB43) -> 5.9814815 | AD43: =SUM(M43:AB43) -> 54 | AH43: =Table3[[#This Row],[Flies_per_Vial]]*Table3[[#This Row],[Vials_Total_UsedInMaze]] -> 0 | AK43: =24*E43 -> 13.066667
A44: 3 | B44: 1 | C44: morn | D44: 24-02-2025 | E44: 0.37847222 | H44: ABCD | I44: S | J44: 2 | K44: A | L44: M | M44: 0 | N44: 0 | O44: 0 | P44: 0 | Q44: 3 | R44: 1 | S44: 1 | T44: 5 | U44: 5 | V44: 7 | W44: 5 | X44: 3 | Y44: 4 | Z44: 6 | AA44: 16 | AB44: 14 | AC44: =SUMPRODUCT(OG_Data!D$1:S$1, M44:AB44) /SUM(M44:AB44) -> 12.485714 | AD44: =SUM(M44:AB44) -> 70 | AE44: 0 | AF44: 6 | AH44: =Table3[[#This Row],[Flies_per_Vial]]*Table3[[#This Row],[Vials_Total_UsedInMaze]] -> 0 | AK44: =24*E44 -> 9.0833333
A45: 3 | B45: 1 | C45: morn | D45: 24-02-2025 | E45: 0.37847222 | H45: ABCD | I45: S | J45: 2 | K45: B | L45: F | M45: 7 | N45: 3 | O45: 1 | P45: 1 | Q45: 1 | R45: 5 | S45: 10 | T45: 7 | U45: 7 | V45: 6 | W45: 8 | X45: 11 | Y45: 7 | Z45: 8 | AA45: 8 | AB45: 5 | AC45: =SUMPRODUCT(OG_Data!D$1:S$1, M45:AB45) /SUM(M45:AB45) -> 9.7578947 | AD45: =SUM(M45:AB45) -> 95 | AE45: 0 | AF45: 6 | AH45: =Table3[[#This Row],[Flies_per_Vial]]*Table3[[#This Row],[Vials_Total_UsedInMaze]] -> 0 | AK45: =24*E45 -> 9.0833333
A46: 3 | B46: 1 | C46: morn | D46: 24-02-2025 | E46: 0.37847222 | H46: ABCD | I46: S | J46: 2 | K46: C | L46: F | M46: 0 | N46: 5 | O46: 5 | P46: 3 | Q46: 4 | R46: 7 | S46: 6 | T46: 9 | U46: 14 | V46: 7 | W46: 5 | X46: 5 | Y46: 1 | Z46: 1 | AA46: 4 | AB46: 4 | AC46: =SUMPRODUCT(OG_Data!D$1:S$1, M46:AB46) /SUM(M46:AB46) -> 8.4375 | AD46: =SUM(M46:AB46) -> 80 | AE46: 0 | AF46: 6 | AH46: =Table3[[#This Row],[Flies_per_Vial]]*Table3[[#This Row],[Vials_Total_UsedInMaze]] -> 0 | AK46: =24*E46 -> 9.0833333
A47: 3 | B47: 1 | C47: morn | D47: 24-02-2025 | E47: 0.37847222 | H47: ABCD | I47: S | J47: 2 | K47: D | L47: M | M47: 0 | N47: 5 | O47: 0 | P47: 4 | Q47: 4 | R47: 2 | S47: 1 | T47: 7 | U47: 5 | V47: 3 | W47: 6 | X47: 4 | Y47: 1 | Z47: 2 | AA47: 3 | AB47: 3 | AC47: =SUMPRODUCT(OG_Data!D$1:S$1, M47:AB47) /SUM(M47:AB47) -> 8.88 | AD47: =SUM(M47:AB47) -> 50 | AE47: 0 | AF47: 6 | AH47: =Table3[[#This Row],[Flies_per_Vial]]*Table3[[#This Row],[Vials_Total_UsedInMaze]] -> 0 | AK47: =24*E47 -> 9.0833333
A48: 3 | B48: 1 | C48: aft | D48: 24-02-2025 | E48: 0.48611111 | H48: ABCD | I48: S | J48: 1 | K48: A | L48: M | M48: 0 | N48: 0 | O48: 0 | P48: 0 | Q48: 1 | R48: 0 | S48: 2 | T48: 2 | U48: 5 | V48: 5 | W48: 23 | X48: 17 | Y48: 28 | Z48: 9 | AA48: 6 | AB48: 0 | AC48: =SUMPRODUCT(OG_Data!D$1:S$1, M48:AB48) /SUM(M48:AB48) -> 11.908163 | AD48: =SUM(M48:AB48) -> 98 | AE48: 0 | AF48: 6 | AH48: =Table3[[#This Row],[Flies_per_Vial]]*Table3[[#This Row],[Vials_Total_UsedInMaze]] -> 0 | AK48: =24*E48 -> 11.666667
A49: 3 | B49: 1 | C49: aft | D49: 24-02-2025 | E49: 0.48611111 | H49: ABCD | I49: S | J49: 1 | K49: B | L49: F | M49: 2 | N49: 1 | O49: 2 | P49: 6 | Q49: 10 | R49: 10 | S49: 12 | T49: 12 | U49: 7 | V49: 7 | W49: 3 | X49: 2 | Y49: 4 | Z49: 4 | AA49: 3 | AB49: 1 | AC49: =SUMPRODUCT(OG_Data!D$1:S$1, M49:AB49) /SUM(M49:AB49) -> 7.9418605 | AD49: =SUM(M49:AB49) -> 86 | AE49: 0 | AF49: 6 | AH49: =Table3[[#This Row],[Flies_per_Vial]]*Table3[[#This Row],[Vials_Total_UsedInMaze]] -> 0 | AK49: =24*E49 -> 11.666667
A50: 3 | B50: 1 | C50: aft | D50: 24-02-2025 | E50: 0.48611111 | H50: ABCD | I50: S | J50: 1 | K50: C | L50: F | M50: 18 | N50: 40 | O50: 17 | P50: 7 | Q50: 12 | R50: 8 | S50: 3 | T50: 2 | U50: 1 | V50: 0 | W50: 3 | X50: 1 | Y50: 1 | Z50: 0 | AA50: 0 | AB50: 1 | AC50: =SUMPRODUCT(OG_Data!D$1:S$1, M50:AB50) /SUM(M50:AB50) -> 3.5526316 | AD50: =SUM(M50:AB50) -> 114 | AE50: 0 | AF50: 6 | AH50: =Table3[[#This Row],[Flies_per_Vial]]*Table3[[#This Row],[Vials_Total_UsedInMaze]] -> 0 | AK50: =24*E50 -> 11.666667
A51: 3 | B51: 1 | C51: aft | D51: 24-02-2025 | E51: 0.48611111 | H51: ABCD | I51: S | J51: 1 | K51: D | L51: M | M51: 1 | N51: 8 | O51: 3 | P51: 3 | Q51: 6 | R51: 10 | S51: 4 | T51: 7 | U51: 15 | V51: 7 | W51: 14 | X51: 7 | Y51: 3 | Z51: 4 | AA51: 0 | AB51: 1 | AC51: =SUMPRODUCT(OG_Data!D$1:S$1, M51:AB51) /SUM(M51:AB51) -> 8.2365591 | AD51: =SUM(M51:AB51) -> 93 | AE51: 0 | AF51: 6 | AH51: =Table3[[#This Row],[Flies_per_Vial]]*Table3[[#This Row],[Vials_Total_UsedInMaze]] -> 0 | AK51: =24*E51 -> 11.666667
A52: 3 | B52: 2 | C52: morn | D52: 25-02-2025 | E52: 0.375 | H52: ABCD | I52: S | J52: 4 | K52: A | L52: M | M52: 0 | N52: 0 | O52: 0 | P52: 1 | Q52: 1 | R52: 0 | S52: 2 | T52: 2 | U52: 5 | V52: 2 | W52: 4 | X52: 4 | Y52: 6 | Z52: 3 | AA52: 17 | AB52: 13 | AC52: =SUMPRODUCT(OG_Data!D$1:S$1, M52:AB52) /SUM(M52:AB52) -> 12.983333 | AD52: =SUM(M52:AB52) -> 60 | AE52: 0 | AF52: 6 | AH52: =Table3[[#This Row],[Flies_per_Vial]]*Table3[[#This Row],[Vials_Total_UsedInMaze]] -> 0 | AK52: =24*E52 -> 9
A53: 3 | B53: 2 | C53: morn | D53: 25-02-2025 | E53: 0.375 | H53: ABCD | I53: S | J53: 4 | K53: B | L53: F | M53: 3 | N53: 3 | O53: 6 | P53: 1 | Q53: 3 | R53: 3 | S53: 13 | T53: 10 | U53: 4 | V53: 7 | W53: 8 | X53: 9 | Y53: 5 | Z53: 4 | AA53: 5 | AB53: 3 | AC53: =SUMPRODUCT(OG_Data!D$1:S$1, M53:AB53) /SUM(M53:AB53) -> 8.9770115 | AD53: =SUM(M53:AB53) -> 87 | AE53: 0 | AF53: 6 | AH53: =Table3[[#This Row],[Flies_per_Vial]]*Table3[[#This Row],[Vials_Total_UsedInMaze]] -> 0 | AK53: =24*E53 -> 9
A54: 3 | B54: 2 | C54: morn | D54: 25-02-2025 | E54: 0.375 | H54: ABCD | I54: S | J54: 4 | K54: C | L54: F | M54: 5 | N54: 8 | O54: 11 | P54: 4 | Q54: 6 | R54: 18 | S54: 1 | T54: 15 | U54: 13 | V54: 4 | W54: 17 | X54: 2 | Y54: 4 | Z54: 0 | AA54: 1 | AB54: 3 | AC54: =SUMPRODUCT(OG_Data!D$1:S$1, M54:AB54) /SUM(M54:AB54) -> 7.3035714 | AD54: =SUM(M54:AB54) -> 112 | AE54: 0 | AF54: 6 | AH54: =Table3[[#This Row],[Flies_per_Vial]]*Table3[[#This Row],[Vials_Total_UsedInMaze]] -> 0 | AK54: =24*E54 -> 9
A55: 3 | B55: 2 | C55: morn | D55: 25-02-2025 | E55: 0.375 | H55: ABCD | I55: S | J55: 4 | K55: D | L55: M | M55: 0 | N55: 3 | O55: 2 | P55: 3 | Q55: 5 | R55: 0 | S55: 3 | T55: 8 | U55: 4 | V55: 4 | W55: 0 | X55: 1 | Y55: 0 | Z55: 1 | AA55: 1 | AB55: 0 | AC55: =SUMPRODUCT(OG_Data!D$1:S$1, M55:AB55) /SUM(M55:AB55) -> 7.1714286 | AD55: =SUM(M55:AB55) -> 35 | AE55: 0 | AF55: 6 | AH55: =Table3[[#This Row],[Flies_per_Vial]]*Table3[[#This Row],[Vials_Total_UsedInMaze]] -> 0 | AK55: =24*E55 -> 9
... A59: 3 | B59: 2 | C59: aft | D59: 25-02-2025 | E59: 0.52291667 | H59: ABCD | I59: S | J59: 3 | K59: D | L59: M | M59: 7 | N59: 15 | O59: 4 | P59: 9 | Q59: 9 | R59: 5 | S59: 3 | T59: 12 | U59: 3 | V59: 5 | W59: 4 | X59: 3 | Y59: 1 | Z59: 2 | AA59: 0 | AB59: 0 | AC59: =SUMPRODUCT(OG_Data!D$1:S$1, M59:AB59) /SUM(M59:AB59) -> 5.7926829 | AD59: =SUM(M59:AB59) -> 82 | AE59: 0 | AF59: 6 | AH59: =Table3[[#This Row],[Flies_per_Vial]]*Table3[[#This Row],[Vials_Total_UsedInMaze]] -> 0 | AK59: =24*E59 -> 12.55
...

Sheet OG_Data
A1: Gen 1 | B1: Term Vials (1: avoid) | C1: Sex | D1: 1 | E1: 2 | F1: 3 | G1: 4 | H1: 5 | I1: 6 | J1: 7 | K1: 8 | L1: 9 | M1: 10 | N1: 11 | O1: 12 | P1: 13 | Q1: 14 | R1: 15 | S1: 16 | U1: Light Score | V1: Totals
A2: day 4 session 1 | B2: maze A | C2: F | D2: 1 | E2: 0 | F2: 0 | G2: 0 | H2: 2 | I2: 2 | J2: 2 | K2: 10 | L2: 4 | M2: 6 | N2: 5 | O2: 2 | P2: 6 | Q2: 3 | R2: 7 | S2: 4 | U2: =SUMPRODUCT(D1:S1, D2:S2) / SUM(D2:S2) -> 10.759259 | V2: =SUM(D2:S2) -> 54
A3: Start: 10:11am | B3: maze B | C3: M | D3: 1 | E3: 2 | F3: 1 | G3: 1 | H3: 2 | I3: 1 | J3: 6 | K3: 12 | L3: 10 | M3: 5 | N3: 7 | O3: 8 | P3: 3 | Q3: 1 | R3: 2 | S3: 1 | U3: =SUMPRODUCT(D1:S1, D3:S3) / SUM(D3:S3) -> 9.1746032 | V3: =SUM(D3:S3) -> 63
A4: End: 12:30pm | B4: maze C | C4: M | D4: 0 | E4: 2 | F4: 0 | G4: 1 | H4: 1 | I4: 0 | J4: 1 | K4: 4 | L4: 0 | M4: 0 | N4: 2 | O4: 0 | P4: 0 | Q4: 0 | R4: 0 | S4: 0 | U4: =SUMPRODUCT(D1:S1, D4:S4) / SUM(D4:S4) -> 6.7272727 | V4: =SUM(D4:S4) -> 11
B5: maze D | C5: F | D5: 2 | E5: 1 | F5: 2 | G5: 0 | H5: 0 | I5: 0 | J5: 0 | K5: 0 | L5: 2 | M5: 1 | N5: 0 | O5: 2 | P5: 1 | Q5: 1 | R5: 1 | S5: 0 | U5: =SUMPRODUCT(D1:S1, D5:S5) / SUM(D5:S5) -> 8 | V5: =SUM(D5:S5) -> 13
B6: flies collected for S1
A8: day 4 session 2 | B8: maze A | C8: F | D8: 1 | E8: 1 | F8: 0 | G8: 0 | H8: 0 | I8: 6 | J8: 2 | K8: 11 | L8: 7 | M8: 15 | N8: 3 | O8: 6 | P8: 7 | Q8: 9 | R8: 5 | S8: 8 | U8: =SUMPRODUCT(D1:S1, D8:S8) / SUM(D8:S8) -> 10.851852 | V8: =SUM(D8:S8) -> 81
A9: Start: 3:25pm | B9: maze B | C9: M | D9: 1 | E9: 3 | F9: 2 | G9: 1 | H9: 2 | I9: 2 | J9: 7 | K9: 7 | L9: 8 | M9: 9 | N9: 4 | O9: 13 | P9: 10 | Q9: 8 | R9: 1 | S9: 5 | U9: =SUMPRODUCT(D1:S1, D9:S9) / SUM(D9:S9) -> 10.156627 | V9: =SUM(D9:S9) -> 83
A10: after 2.5hrs many flies are still at start | B10: maze C | C10: M | D10: 0 | E10: 0 | F10: 0 | G10: 0 | H10: 0 | I10: 0 | J10: 1 | K10: 2 | L10: 1 | M10: 0 | N10: 6 | O10: 3 | P10: 0 | Q10: 1 | R10: 2 | S10: 1 | U10: =SUMPRODUCT(D1:S1, D10:S10) / SUM(D10:S10) -> 11.411765 | V10: =SUM(D10:S10) -> 17
A11: End: 6:18 | B11: maze D | C11: F | D11: 0 | E11: 2 | F11: 0 | G11: 2 | H11: 0 | I11: 0 | J11: 1 | K11: 0 | L11: 0 | M11: 0 | N11: 0 | O11: 0 | P11: 1 | Q11: 0 | R11: 0 | S11: 0 | U11: =SUMPRODUCT(D1:S1, D11:S11) / SUM(D11:S11) -> 5.3333333 | V11: =SUM(D11:S11) -> 6
B12: flies collected for S2
A14: day 5 session 1 | B14: maze A | C14: M | D14: 0 | E14: 1 | F14: 0 | G14: 0 | H14: 1 | I14: 1 | J14: 1 | K14: 4 | L14: 6 | M14: 6 | N14: 4 | O14: 0 | P14: 0 | Q14: 1 | R14: 1 | S14: 0 | U14: =SUMPRODUCT(D1:S1, D14:S14) / SUM(D14:S14) -> 9.1923077 | V14: =SUM(D14:S14) -> 26
A15: 9:11am - 10:30am | B15: maze B | C15: F | D15: 1 | E15: 2 | F15: 0 | G15: 0 | H15: 3 | I15: 0 | J15: 6 | K15: 8 | L15: 3 | M15: 7 | N15: 5 | O15: 5 | P15: 9 | Q15: 7 | R15: 5 | S15: 2 | U15: =SUMPRODUCT(D1:S1, D15:S15) / SUM(D15:S15) -> 10.47619 | V15: =SUM(D15:S15) -> 63
B16: maze A2 | C16: M | D16: 0 | E16: 4 | F16: 2 | G16: 0 | H16: 3 | I16: 4 | J16: 4 | K16: 11 | L16: 7 | M16: 7 | N16: 15 | O16: 10 | P16: 5 | Q16: 10 | R16: 2 | S16: 2 | U16: =SUMPRODUCT(D1:S1, D16:S16) / SUM(D16:S16) -> 9.9302326 | V16: =SUM(D16:S16) -> 86
A17: 11:15am-12:45pm | B17: maze B2 | C17: F | D17: 4 | E17: 8 | F17: 8 | G17: 4 | H17: 4 | I17: 5 | J17: 6 | K17: 11 | L17: 9 | M17: 6 | N17: 10 | O17: 9 | P17: 3 | Q17: 1 | R17: 3 | S17: 2 | U17: =SUMPRODUCT(D1:S1, D17:S17) / SUM(D17:S17) -> 7.8387097 | V17: =SUM(D17:S17) -> 93
B18: flies collected for S3
A20: day 5 session 2 | B20: maze A | C20: M | D20: 0 | E20: 0 | F20: 0 | G20: 1 | H20: 5 | I20: 3 | J20: 10 | K20: 3 | L20: 6 | M20: 17 | N20: 15 | O20: 6 | P20: 6 | Q20: 3 | R20: 0 | S20: 2 | U20: =SUMPRODUCT(D1:S1, D20:S20) / SUM(D20:S20) -> 9.7922078 | V20: =SUM(D20:S20) -> 77
A21: 1:36pm-3:25pm | B21: maze B | C21: F | D21: 2 | E21: 0 | F21: 6 | G21: 5 | H21: 4 | I21: 1 | J21: 4 | K21: 6 | L21: 4 | M21: 1 | N21: 2 | O21: 3 | P21: 1 | Q21: 0 | R21: 1 | S21: 0 | U21: =SUMPRODUCT(D1:S1, D21:S21) / SUM(D21:S21) -> 6.85 | V21: =SUM(D21:S21) -> 40
B22: maze A2 | C22: M | D22: 0 | E22: 0 | F22: 1 | G22: 0 | H22: 3 | I22: 3 | J22: 8 | K22: 4 | L22: 1 | M22: 8 | N22: 7 | O22: 10 | P22: 9 | Q22: 6 | R22: 0 | S22: 1 | U22: =SUMPRODUCT(D1:S1, D22:S22) / SUM(D22:S22) -> 10.278689 | V22: =SUM(D22:S22) -> 61
A23: 3:50pm-6:15pm | B23: maze B2 | C23: F | D23: 0 | E23: 0 | F23: 3 | G23: 1 | H23: 3 | I23: 6 | J23: 3 | K23: 8 | L23: 5 | M23: 0 | N23: 2 | O23: 5 | P23: 2 | Q23: 3 | R23: 0 | S23: 1 | U23: =SUMPRODUCT(D1:S1, D23:S23) / SUM(D23:S23) -> 8.5714286 | V23: =SUM(D23:S23) -> 42
B24: flies collected for S4
A26: day 5 session 3 | B26: maze A | C26: M | D26: 1 | E26: 1 | F26: 3 | G26: 1 | H26: 2 | I26: 0 | J26: 7 | K26: 3 | L26: 1 | M26: 2 | N26: 1 | O26: 6 | P26: 3 | Q26: 0 | R26: 1 | S26: 2 | U26: =SUMPRODUCT(D1:S1, D26:S26) / SUM(D26:S26) -> 8.7352941 | V26: =SUM(D26:S26) -> 34
A27: 6:42pm-9pm | B27: maze B | C27: F | D27: 0 | E27: 0 | F27: 0 | G27: 0 | H27: 1 | I27: 2 | J27: 2 | K27: 4 | L27: 3 | M27: 4 | N27: 3 | O27: 3 | P27: 3 | Q27: 1 | R27: 0 | S27: 1 | U27: =SUMPRODUCT(D1:S1, D27:S27) / SUM(D27:S27) -> 9.9259259 | V27: =SUM(D27:S27) -> 27
B28: flies collected for S1
B29: flies collected for S2
A31: day 6 session 1 | B31: maze A | C31: M | D31: 0 | E31: 0 | F31: 0 | G31: 0 | H31: 1 | I31: 1 | J31: 2 | K31: 6 | L31: 4 | M31: 14 | N31: 6 | O31: 5 | P31: 2 | Q31: 4 | R31: 1 | S31: 2 | U31: =SUMPRODUCT(D1:S1, D31:S31) / SUM(D31:S31) -> 10.5 | V31: =SUM(D31:S31) -> 48
A32: 10am-11:17am | B32: maze B | C32: F | D32: 4 | E32: 3 | F32: 0 | G32: 0 | H32: 2 | I32: 2 | J32: 4 | K32: 3 | L32: 0 | M32: 5 | N32: 3 | O32: 9 | P32: 5 | Q32: 4 | R32: 2 | S32: 3 | U32: =SUMPRODUCT(D1:S1, D32:S32) / SUM(D32:S32) -> 9.6734694 | V32: =SUM(D32:S32) -> 49
B33: flies collected for C1
A36: day 6 session 2 | B36: maze A | C36: M | D36: 0 | E36: 1 | F36: 0 | G36: 2 | H36: 1 | I36: 1 | J36: 6 | K36: 10 | L36: 8 | M36: 6 | N36: 10 | O36: 9 | P36: 7 | Q36: 2 | R36: 5 | S36: 0 | U36: =SUMPRODUCT(D1:S1, D36:S36) / SUM(D36:S36) -> 10.102941 | V36: =SUM(D36:S36) -> 68
A37: 11:42am-1:40pm | B37: maze B | C37: F | D37: 9 | E37: 9 | F37: 3 | G37: 0 | H37: 1 | I37: 2 | J37: 1 | K37: 1 | L37: 2 | M37: 3 | N37: 2 | O37: 2 | P37: 0 | Q37: 2 | R37: 6 | S37: 1 | U37: =SUMPRODUCT(D1:S1, D37:S37) / SUM(D37:S37) -> 6.7272727 | V37: =SUM(D37:S37) -> 44
B38: flies collected for C2
A41: day 6 session 3 | B41: maze A | C41: M | D41: 0 | E41: 0 | F41: 0 | G41: 0 | H41: 3 | I41: 2 | J41: 4 | K41: 7 | L41: 2 | M41: 4 | N41: 9 | O41: 8 | P41: 6 | Q41: 4 | R41: 8 | S41: 2 | U41: =SUMPRODUCT(D1:S1, D41:S41) / SUM(D41:S41) -> 11.016949 | V41: =SUM(D41:S41) -> 59
A42: 2:04pm-4pm | B42: maze B | C42: F | D42: 9 | E42: 5 | F42: 4 | G42: 1 | H42: 3 | I42: 2 | J42: 1 | K42: 3 | L42: 2 | M42: 3 | N42: 0 | O42: 0 | P42: 1 | Q42: 5 | R42: 3 | S42: 3 | U42: =SUMPRODUCT(D1:S1, D42:S42) / SUM(D42:S42) -> 7.0444444 | V42: =SUM(D42:S42) -> 45
B43: flies collected for C3
A45: day 6 session 4 | B45: maze A | C45: M | D45: 0 | E45: 1 | F45: 0 | G45: 0 | H45: 2 | I45: 6 | J45: 4 | K45: 5 | L45: 3 | M45: 8 | N45: 9 | O45: 6 | P45: 10 | Q45: 5 | R45: 6 | S45: 1 | U45: =SUMPRODUCT(D1:S1, D45:S45) / SUM(D45:S45) -> 10.606061 | V45: =SUM(D45:S45) -> 66
A46: 4:18pm-7pm | B46: maze B | C46: F | D46: 14 | E46: 13 | F46: 4 | G46: 1 | H46: 2 | I46: 2 | J46: 4 | K46: 4 | L46: 3 | M46: 4 | N46: 1 | O46: 3 | P46: 6 | Q46: 7 | R46: 6 | S46: 8 | U46: =SUMPRODUCT(D1:S1, D46:S46) / SUM(D46:S46) -> 7.8780488 | V46: =SUM(D46:S46) -> 82
B47: flies collected for C4
A49: Gen 2 | B49: Term Vials | C49: Sex | D49: 1 | E49: 2 | F49: 3 | G49: 4 | H49: 5 | I49: 6 | J49: 7 | K49: 8 | L49: 9 | M49: 10 | N49: 11 | O49: 12 | P49: 13 | Q49: 14 | R49: 15 | S49: 16
A50: day 4 session 1 | B50: S1
A51: 11:07am | B51: maze A | C51: F | D51: 0 | E51: 0 | F51: 1 | G51: 2 | H51: 2 | I51: 2 | J51: 2 | K51: 4 | L51: 9 | M51: 10 | N51: 10 | O51: 7 | P51: 4 | Q51: 2 | R51: 14 | S51: 3 | U51: =SUMPRODUCT(D49:S49, D51:S51) / SUM(D51:S51) -> 11 | V51: =SUM(D51:S51) -> 72
...
